Workbook

Sheet Matriz Cobertura
A1: Región | B1: Localidad | C1: Población | D1: Zona | E1: Zonificación | F1: Rutas Nacionales | G1: Distribuidor | H1: Marca | I1: Población | J1: Parque Automotor | K1: Autos
A2: CABA | B2: CABA | C2: =1560853*0.5 -> 780426.5 | D2: Norte | E2: 1 | G2: PINTURERIA DEL FONDO SA | H2: PPG | I2: 3121707 | J2: 1398169 | K2: 1106730
A3: CABA | B3: CABA | C3: =1560853*0.5 -> 780426.5 | D3: Norte | E3: 2 | G3: AISENBERG Y CIA SA | H3: 2K
A4: CABA | B4: CABA | C4: =1560853*0.5 -> 780426.5 | D4: Sur | E4: 2 | G4: PICCIN HNOS. | H4: PPG
A5: CABA | B5: CABA | C5: =1560853*0.25 -> 390213.25 | D5: Sur | E5: 2 | G5: Fernandez | H5: PPG
A6: CABA | B6: CABA | C6: =1560853*0.25 -> 390213.25 | D6: Sur | E6: 2 | G6: ANGRIGIANI S.A. | H6: 2K
A7: CABA | B7: CABA | C7: 1 | D7: Sur | E7: 3 | G7: OSVALDO BAIGORROTEGUI | H7: 2K
A8: BA GBA | B8: La Matanza | C8: 1841247 | D8: Oeste | E8: 2 | G8: ZANCHETTA HNOS SH | H8: PPG | I8: =VLOOKUP(B8,'P Bs As'!$B$4:$I$41,2,FALSE) -> 1841247 | J8: =VLOOKUP(B8,'P Bs As'!$B$4:$I$41,7,FALSE) -> 353947.77 | K8: =+J8*0.78 -> 276079.26
A9: BA GBA | B9: Lomas de Zamora | C9: 690323 | D9: Oeste | E9: 3 | G9: DISTRIBUIDORA COLESUR SRL | I9: =VLOOKUP(B9,'P Bs As'!$B$4:$I$41,2,FALSE) -> 690323 | J9: =VLOOKUP(B9,'P Bs As'!$B$4:$I$41,7,FALSE) -> 206360.49 | K9: =+J9*0.78 -> 160961.18
A10: BA GBA | B10: Quilmes | C10: 633391 | D10: Sur | E10: 3 | G10: PINTURERIAS TRAVERSA SRL | H10: PPG | I10: =VLOOKUP(B10,'P Bs As'!$B$4:$I$41,2,FALSE) -> 633391 | J10: =VLOOKUP(B10,'P Bs As'!$B$4:$I$41,7,FALSE) -> 193086.6 | K10: =+J10*0.78 -> 150607.55
A11: BA GBA | B11: Almirante Brown | C11: 584827 | D11: Sur | E11: 3 | G11: GIANATIEMPO PABLO | H11: PPG | I11: =VLOOKUP(B11,'P Bs As'!$B$4:$I$41,2,FALSE) -> 584827 | J11: =VLOOKUP(B11,'P Bs As'!$B$4:$I$41,7,FALSE) -> 163193.61 | K11: =+J11*0.78 -> 127291.02
A12: BA GBA | B12: Merlo | C12: 582486 | D12: Oeste | E12: 2 | I12: =VLOOKUP(B12,'P Bs As'!$B$4:$I$41,2,FALSE) -> 582486 | J12: =VLOOKUP(B12,'P Bs As'!$B$4:$I$41,7,FALSE) -> 127986.6 | K12: =+J12*0.78 -> 99829.548
A13: BA GBA | B13: Moreno | C13: 576632 | D13: Oeste | E13: 2 | G13: LUPATINI Y CIA | H13: PPG | I13: =VLOOKUP(B13,'P Bs As'!$B$4:$I$41,2,FALSE) -> 576632 | J13: =VLOOKUP(B13,'P Bs As'!$B$4:$I$41,7,FALSE) -> 128947.29 | K13: =+J13*0.78 -> 100578.89
A14: BA GBA | B14: Florencio Varela | C14: 496433 | D14: Sur | E14: 3 | I14: =VLOOKUP(B14,'P Bs As'!$B$4:$I$41,2,FALSE) -> 496433 | J14: =VLOOKUP(B14,'P Bs As'!$B$4:$I$41,7,FALSE) -> 111832.5 | K14: =+J14*0.78 -> 87229.35
A15: BA GBA | B15: Lanús | C15: 461267 | D15: Sur | E15: 3 | G15: PINT Y FERRET EL SOL SA | H15: PPG | I15: =VLOOKUP(B15,'P Bs As'!$B$4:$I$41,2,FALSE) -> 461267 | J15: =VLOOKUP(B15,'P Bs As'!$B$4:$I$41,7,FALSE) -> 163583.28 | K15: =+J15*0.78 -> 127594.96
A16: BA GBA | B16: Lanús | C16: 1 | D16: Sur | E16: 3 | H16: PPG | I16: =VLOOKUP(B16,'P Bs As'!$B$4:$I$41,2,FALSE) -> 461267 | J16: =VLOOKUP(B16,'P Bs As'!$B$4:$I$41,7,FALSE) -> 163583.28 | K16: =+J16*0.78 -> 127594.96
A17: BA GBA | B17: General San Martín | C17: 450575 | D17: Norte | E17: 1 | G17: PINTURERIA DEL FONDO SA | H17: PPG | I17: =VLOOKUP(B17,'P Bs As'!$B$4:$I$41,2,FALSE) -> 450575 | J17: =VLOOKUP(B17,'P Bs As'!$B$4:$I$41,7,FALSE) -> 119328.3 | K17: =+J17*0.78 -> 93076.074
A18: BA GBA | B18: Tigre | C18: 446949 | D18: Norte | E18: 1 | G18: PINTE CANAL SRL | H18: PPG | I18: =VLOOKUP(B18,'P Bs As'!$B$4:$I$41,2,FALSE) -> 446949 | J18: =VLOOKUP(B18,'P Bs As'!$B$4:$I$41,7,FALSE) -> 141229.8 | K18: =+J18*0.78 -> 110159.24
A19: BA GBA | B19: Pilar | C19: =394754*0.5 -> 197377 | D19: Norte | E19: 1 | G19: PINTURERIA DEL FONDO SA | H19: PPG | I19: =VLOOKUP(B19,'P Bs As'!$B$4:$I$41,2,FALSE) -> 394754 | J19: =VLOOKUP(B19,'P Bs As'!$B$4:$I$41,7,FALSE) -> 109345.68 | K19: =+J19*0.78 -> 85289.63
A20: BA GBA | B20: Pilar | C20: =394754*0.5 -> 197377 | D20: Norte | E20: 1 | G20: PINTURERIAS BRIAGO S.A | H20: 2K | I20: =VLOOKUP(B20,'P Bs As'!$B$4:$I$41,2,FALSE) -> 394754 | J20: =VLOOKUP(B20,'P Bs As'!$B$4:$I$41,7,FALSE) -> 109345.68 | K20: =+J20*0.78 -> 85289.63
A21: BA GBA | B21: Avellaneda | C21: 367554 | D21: Sur | E21: 3 | G21: Faranda | H21: PPG | I21: =VLOOKUP(B21,'P Bs As'!$B$4:$I$41,2,FALSE) -> 367554 | J21: =VLOOKUP(B21,'P Bs As'!$B$4:$I$41,7,FALSE) -> 123414.72 | K21: =+J21*0.78 -> 96263.482
A22: BA GBA | B22: Tres de Febrero | C22: 364176 | D22: Oeste | E22: 1 | G22: LUPATINI Y CIA | H22: PPG | I22: =VLOOKUP(B22,'P Bs As'!$B$4:$I$41,2,FALSE) -> 364176 | J22: =VLOOKUP(B22,'P Bs As'!$B$4:$I$41,7,FALSE) -> 131348.55 | K22: =+J22*0.78 -> 102451.87
A23: BA GBA | B23: Berazategui | C23: 358712 | D23: Sur | E23: 3 | I23: =VLOOKUP(B23,'P Bs As'!$B$4:$I$41,2,FALSE) -> 358712 | J23: =VLOOKUP(B23,'P Bs As'!$B$4:$I$41,7,FALSE) -> 105932.58 | K23: =+J23*0.78 -> 82627.412
A24: BA GBA | B24: Malvinas Argentinas | C24: 350674 | D24: Norte | E24: 1 | I24: =VLOOKUP(B24,'P Bs As'!$B$4:$I$41,2,FALSE) -> 350674 | J24: =VLOOKUP(B24,'P Bs As'!$B$4:$I$41,7,FALSE) -> 97643.49 | K24: =+J24*0.78 -> 76161.922
A25: BA GBA | B25: Esteban Echeverría | C25: 338480 | D25: Sur | E25: 3 | I25: =VLOOKUP(B25,'P Bs As'!$B$4:$I$41,2,FALSE) -> 338480 | J25: =VLOOKUP(B25,'P Bs As'!$B$4:$I$41,7,FALSE) -> 99200.31 | K25: =+J25*0.78 -> 77376.242
A26: BA GBA | B26: Morón | C26: 331183 | D26: Oeste | E26: 2 | G26: LUPATINI Y CIA / CAPELLI | H26: PPG | I26: =VLOOKUP(B26,'P Bs As'!$B$4:$I$41,2,FALSE) -> 331183 | J26: =VLOOKUP(B26,'P Bs As'!$B$4:$I$41,7,FALSE) -> 136245.93 | K26: =+J26*0.78 -> 106271.83
A27: BA GBA | B27: San Miguel | C27: 328835 | D27: Norte | E27: 1 | I27: =VLOOKUP(B27,'P Bs As'!$B$4:$I$41,2,FALSE) -> 328835 | J27: =VLOOKUP(B27,'P Bs As'!$B$4:$I$41,7,FALSE) -> 95619.81 | K27: =+J27*0.78 -> 74583.452
A28: BA GBA | B28: José C. Paz | C28: 326992 | D28: Norte | E28: 1 | I28: =VLOOKUP(B28,'P Bs As'!$B$4:$I$41,2,FALSE) -> 326992 | J28: =VLOOKUP(B28,'P Bs As'!$B$4:$I$41,7,FALSE) -> 76485.06 | K28: =+J28*0.78 -> 59658.347
A29: BA GBA | B29: San Isidro | C29: 297282 | D29: Norte | E29: 1 | G29: PINTURERIA DEL FONDO SA | H29: PPG | I29: =VLOOKUP(B29,'P Bs As'!$B$4:$I$41,2,FALSE) -> 297282 | J29: =VLOOKUP(B29,'P Bs As'!$B$4:$I$41,7,FALSE) -> 110325.9 | K29: =+J29*0.78 -> 86054.202
A30: BA GBA | B30: Vicente López | C30: 282281 | D30: Norte | E30: 1 | G30: PINTURERIA DEL FONDO SA | H30: PPG | I30: =VLOOKUP(B30,'P Bs As'!$B$4:$I$41,2,FALSE) -> 282281 | J30: =VLOOKUP(B30,'P Bs As'!$B$4:$I$41,7,FALSE) -> 117298.11 | K30: =+J30*0.78 -> 91492.526
A31: BA GBA | B31: Escobar | C31: 256268 | D31: Norte | E31: 1 | G31: BARADERO PINTURAS | H31: PPG | I31: =VLOOKUP(B31,'P Bs As'!$B$4:$I$41,2,FALSE) -> 256268 | J31: =VLOOKUP(B31,'P Bs As'!$B$4:$I$41,7,FALSE) -> 62418.81 | K31: =+J31*0.78 -> 48686.672
A32: BA GBA | B32: Ezeiza | C32: 201511 | D32: Sur | E32: 3 | I32: =VLOOKUP(B32,'P Bs As'!$B$4:$I$41,2,FALSE) -> 201511 | J32: =VLOOKUP(B32,'P Bs As'!$B$4:$I$41,7,FALSE) -> 0 | K32: =+J32*0.78 -> 0
A33: BA GBA | B33: Hurlingham | C33: 185641 | D33: Oeste | E33: 2 | G33: LUPATINI Y CIA | H33: PPG | I33: =VLOOKUP(B33,'P Bs As'!$B$4:$I$41,2,FALSE) -> 185641 | J33: =VLOOKUP(B33,'P Bs As'!$B$4:$I$41,7,FALSE) -> 40114.62 | K33: =+J33*0.78 -> 31289.404
A34: BA GBA | B34: Ituzaingó | C34: 180232 | D34: Oeste | E34: 2 | G34: LUPATINI Y CIA | H34: PPG | I34: =VLOOKUP(B34,'P Bs As'!$B$4:$I$41,2,FALSE) -> 180232 | J34: =VLOOKUP(B34,'P Bs As'!$B$4:$I$41,7,FALSE) -> 71588.61 | K34: =+J34*0.78 -> 55839.116
A35: BA GBA | B35: San Fernando | C35: =171616*0.5 -> 85808 | D35: Norte | E35: 1 | G35: PINTE CANAL SRL | H35: PPG | I35: =VLOOKUP(B35,'P Bs As'!$B$4:$I$41,2,FALSE) -> 171616 | J35: =VLOOKUP(B35,'P Bs As'!$B$4:$I$41,7,FALSE) -> 56084.58 | K35: =+J35*0.78 -> 43745.972
A36: BA GBA | B36: San Fernando | C36: =171616*0.5 -> 85808 | D36: Norte | E36: 1 | G36: CAPORASO JUAN CARLOS | H36: 2K | I36: =VLOOKUP(B36,'P Bs As'!$B$4:$I$41,2,FALSE) -> 171616 | J36: =VLOOKUP(B36,'P Bs As'!$B$4:$I$41,7,FALSE) -> 56084.58 | K36: =+J36*0.78 -> 43745.972
A37: BA GBA | B37: General Rodríguez | C37: 142709 | D37: Oeste | E37: 2 | G37: LUPATINI Y CIA | H37: PPG | I37: =VLOOKUP(B37,'P Bs As'!$B$4:$I$41,2,FALSE) -> 142709 | J37: =VLOOKUP(B37,'P Bs As'!$B$4:$I$41,7,FALSE) -> 35686.89 | K37: =+J37*0.78 -> 27835.774
A38: BA GBA | B38: Presidente Perón | C38: 102106 | D38: Sur | E38: 3 | H38: PPG | I38: =VLOOKUP(B38,'P Bs As'!$B$4:$I$41,2,FALSE) -> 102106 | J38: =VLOOKUP(B38,'P Bs As'!$B$4:$I$41,7,FALSE) -> 0 | K38: =+J38*0.78 -> 0
A39: BA GBA | B39: San Vicente | C39: 98215 | D39: Sur | E39: 3 | I39: =VLOOKUP(B39,'P Bs As'!$B$4:$I$41,2,FALSE) -> 98215 | J39: =VLOOKUP(B39,'P Bs As'!$B$4:$I$41,7,FALSE) -> 43892.28 | K39: =+J39*0.78 -> 34235.978
A40: BA GBA | B40: Cañuelas | C40: 70684 | D40: Oeste | E40: 3 | I40: =VLOOKUP(B40,'P Bs As'!$B$4:$I$41,2,FALSE) -> 70684 | J40: =VLOOKUP(B40,'P Bs As'!$B$4:$I$41,7,FALSE) -> 0 | K40: =+J40*0.78 -> 0
...

Sheet P Bs As
A1: Buenos Aires | B1: (Base 2021 - DNRPA)
A3: Región | B3: Localidad | C3: Población | D3: Zona | E3: Zonificación/tecnico | F3: Rutas Nacionales | G3: Distribuidor | H3: Parque Automotor | I3: Autos | J3: Promedio vehículos que reparan | K3: Promedio de Reparación (paños) | L3: Habitante x Vehículo
A4: GBA | B4: La Matanza | C4: 1841247 | D4: Oeste | E4: 2 | H4: =+N4*0.93 -> 353947.77 | I4: =+H4*0.78 -> 276079.26 | J4: =+I4*0.1599 -> 44145.074 | K4: =+J4*3 -> 132435.22 | L4: =+C4/H4 -> 5.2020302 | N4: 380589
A5: GBA | B5: Lomas de Zamora | C5: 690323 | D5: Oeste | E5: 3 | H5: =+N5*0.93 -> 206360.49 | I5: =+H5*0.78 -> 160961.18 | J5: =+I5*0.1599 -> 25737.693 | K5: =+J5*3 -> 77213.079 | L5: =+C5/H5 -> 3.3452285 | N5: 221893
A6: GBA | B6: Quilmes | C6: 633391 | D6: Sur | E6: 3 | H6: =+N6*0.93 -> 193086.6 | I6: =+H6*0.78 -> 150607.55 | J6: =+I6*0.1599 -> 24082.147 | K6: =+J6*3 -> 72246.441 | L6: =+C6/H6 -> 3.2803467 | N6: 207620
A7: GBA | B7: Almirante Brown | C7: 584827 | D7: Sur | E7: 3 | H7: =+N7*0.93 -> 163193.61 | I7: =+H7*0.78 -> 127291.02 | J7: =+I7*0.1599 -> 20353.833 | K7: =+J7*3 -> 61061.5 | L7: =+C7/H7 -> 3.5836391 | N7: 175477
A8: GBA | B8: Merlo | C8: 582486 | D8: Oeste | E8: 2 | H8: =+N8*0.93 -> 127986.6 | I8: =+H8*0.78 -> 99829.548 | J8: =+I8*0.1599 -> 15962.745 | K8: =+J8*3 -> 47888.234 | L8: =+C8/H8 -> 4.5511483 | N8: 137620
A9: GBA | B9: Moreno | C9: 576632 | D9: Oeste | E9: 2 | H9: =+N9*0.93 -> 128947.29 | I9: =+H9*0.78 -> 100578.89 | J9: =+I9*0.1599 -> 16082.564 | K9: =+J9*3 -> 48247.692 | L9: =+C9/H9 -> 4.4718427 | N9: 138653
A10: GBA | B10: Florencio Varela | C10: 496433 | D10: Sur | E10: 3 | H10: =+N10*0.93 -> 111832.5 | I10: =+H10*0.78 -> 87229.35 | J10: =+I10*0.1599 -> 13947.973 | K10: =+J10*3 -> 41843.919 | L10: =+C10/H10 -> 4.4390763 | N10: 120250
A11: GBA | B11: Lanús | C11: 461267 | D11: Sur | E11: 3 | H11: =+N11*0.93 -> 163583.28 | I11: =+H11*0.78 -> 127594.96 | J11: =+I11*0.1599 -> 20402.434 | K11: =+J11*3 -> 61207.302 | L11: =+C11/H11 -> 2.8197686 | N11: 175896
A12: GBA | B12: General San Martín | C12: 450575 | D12: Norte | E12: 1 | H12: =+N12*0.93 -> 119328.3 | I12: =+H12*0.78 -> 93076.074 | J12: =+I12*0.1599 -> 14882.864 | K12: =+J12*3 -> 44648.593 | L12: =+C12/H12 -> 3.7759274 | N12: =84996+43314 -> 128310
A13: GBA | B13: Tigre | C13: 446949 | D13: Norte | E13: 1 | H13: =+N13*0.93 -> 141229.8 | I13: =+H13*0.78 -> 110159.24 | J13: =+I13*0.1599 -> 17614.463 | K13: =+J13*3 -> 52843.389 | L13: =+C13/H13 -> 3.1646933 | N13: 151860
A14: GBA | B14: Pilar | C14: 394754 | D14: Norte | E14: 1 | H14: =+N14*0.93 -> 109345.68 | I14: =+H14*0.78 -> 85289.63 | J14: =+I14*0.1599 -> 13637.812 | K14: =+J14*3 -> 40913.436 | L14: =+C14/H14 -> 3.6101472 | N14: 117576
A15: GBA | B15: Avellaneda | C15: 367554 | D15: Sur | E15: 3 | H15: =+N15*0.93 -> 123414.72 | I15: =+H15*0.78 -> 96263.482 | J15: =+I15*0.1599 -> 15392.531 | K15: =+J15*3 -> 46177.592 | L15: =+C15/H15 -> 2.9782023 | N15: =88248+44456 -> 132704
A16: GBA | B16: Tres de Febrero | C16: 364176 | D16: Oeste | E16: 1 | H16: =+N16*0.93 -> 131348.55 | I16: =+H16*0.78 -> 102451.87 | J16: =+I16*0.1599 -> 16382.054 | K16: =+J16*3 -> 49146.162 | L16: =+C16/H16 -> 2.7725925 | N16: 141235
A17: GBA | B17: Berazategui | C17: 358712 | D17: Sur | E17: 2 | H17: =+N17*0.93 -> 105932.58 | I17: =+H17*0.78 -> 82627.412 | J17: =+I17*0.1599 -> 13212.123 | K17: =+J17*3 -> 39636.37 | L17: =+C17/H17 -> 3.3862292 | N17: 113906
A18: GBA | B18: Malvinas Argentinas | C18: 350674 | D18: Norte | E18: 1 | H18: =+N18*0.93 -> 97643.49 | I18: =+H18*0.78 -> 76161.922 | J18: =+I18*0.1599 -> 12178.291 | K18: =+J18*3 -> 36534.874 | L18: =+C18/H18 -> 3.591371 | N18: =48960+56033 -> 104993
A19: GBA | B19: Esteban Echeverría | C19: 338480 | D19: Sur | E19: 3 | H19: =+N19*0.93 -> 99200.31 | I19: =+H19*0.78 -> 77376.242 | J19: =+I19*0.1599 -> 12372.461 | K19: =+J19*3 -> 37117.383 | L19: =+C19/H19 -> 3.4120861 | N19: =69275+37392 -> 106667
A20: GBA | B20: Morón | C20: 331183 | D20: Oeste | E20: 2 | H20: =+N20*0.93 -> 136245.93 | I20: =+H20*0.78 -> 106271.83 | J20: =+I20*0.1599 -> 16992.865 | K20: =+J20*3 -> 50978.595 | L20: =+C20/H20 -> 2.4307735 | N20: =98458+48043 -> 146501
A21: GBA | B21: San Miguel | C21: 328835 | D21: Norte | E21: 1 | H21: =+N21*0.93 -> 95619.81 | I21: =+H21*0.78 -> 74583.452 | J21: =+I21*0.1599 -> 11925.894 | K21: =+J21*3 -> 35777.682 | L21: =+C21/H21 -> 3.438984 | N21: 102817
A22: GBA | B22: José C. Paz | C22: 326992 | D22: Norte | E22: 1 | H22: =+N22*0.93 -> 76485.06 | I22: =+H22*0.78 -> 59658.347 | J22: =+I22*0.1599 -> 9539.3697 | K22: =+J22*3 -> 28618.109 | L22: =+C22/H22 -> 4.2752402 | N22: 82242
A23: GBA | B23: San Isidro | C23: 297282 | D23: Norte | E23: 1 | H23: =+N23*0.93 -> 110325.9 | I23: =+H23*0.78 -> 86054.202 | J23: =+I23*0.1599 -> 13760.067 | K23: =+J23*3 -> 41280.201 | L23: =+C23/H23 -> 2.6945803 | N23: 118630
A24: GBA | B24: Vicente López | C24: 282281 | D24: Norte | E24: 1 | H24: =+N24*0.93 -> 117298.11 | I24: =+H24*0.78 -> 91492.526 | J24: =+I24*0.1599 -> 14629.655 | K24: =+J24*3 -> 43888.965 | L24: =+C24/H24 -> 2.4065264 | N24: =90165+35962 -> 126127
A25: GBA | B25: Escobar | C25: 256268 | D25: Norte | E25: 1 | H25: =+N25*0.93 -> 62418.81 | I25: =+H25*0.78 -> 48686.672 | J25: =+I25*0.1599 -> 7784.9988 | K25: =+J25*3 -> 23354.996 | L25: =+C25/H25 -> 4.1056214 | N25: 67117
A26: GBA | B26: Ezeiza | C26: 201511 | D26: Sur | E26: 3 | H26: =+N26*0.93 -> 0 | I26: =+H26*0.78 -> 0 | J26: =+I26*0.1599 -> 0 | K26: =+J26*3 -> 0 | L26: =+C26/H26 -> #DIV/0!
A27: GBA | B27: Hurlingham | C27: 185641 | D27: Oeste | E27: 2 | H27: =+N27*0.93 -> 40114.62 | I27: =+H27*0.78 -> 31289.404 | J27: =+I27*0.1599 -> 5003.1756 | K27: =+J27*3 -> 15009.527 | L27: =+C27/H27 -> 4.6277641 | N27: 43134
A28: GBA | B28: Ituzaingó | C28: 180232 | D28: Oeste | E28: 2 | H28: =+N28*0.93 -> 71588.61 | I28: =+H28*0.78 -> 55839.116 | J28: =+I28*0.1599 -> 8928.6746 | K28: =+J28*3 -> 26786.024 | L28: =+C28/H28 -> 2.5176072 | N28: 76977
A29: GBA | B29: San Fernando | C29: 171616 | D29: Norte | E29: 1 | H29: =+N29*0.93 -> 56084.58 | I29: =+H29*0.78 -> 43745.972 | J29: =+I29*0.1599 -> 6994.981 | K29: =+J29*3 -> 20984.943 | L29: =+C29/H29 -> 3.0599498 | N29: 60306
A30: GBA | B30: General Rodríguez | C30: 142709 | D30: Oeste | E30: 2 | H30: =+N30*0.93 -> 35686.89 | I30: =+H30*0.78 -> 27835.774 | J30: =+I30*0.1599 -> 4450.9403 | K30: =+J30*3 -> 13352.821 | L30: =+C30/H30 -> 3.9989195 | N30: 38373
A31: GBA | B31: Presidente Perón | C31: 102106 | D31: Sur | E31: 3 | H31: =+N31*0.93 -> 0 | I31: =+H31*0.78 -> 0 | J31: =+I31*0.1599 -> 0 | K31: =+J31*3 -> 0 | L31: =+C31/H31 -> #DIV/0!
A32: GBA | B32: San Vicente | C32: 98215 | D32: Sur | E32: 3 | H32: =+N32*0.93 -> 43892.28 | I32: =+H32*0.78 -> 34235.978 | J32: =+I32*0.1599 -> 5474.3329 | K32: =+J32*3 -> 16422.999 | L32: =+C32/H32 -> 2.2376372 | N32: 47196
A33: GBA | B33: Cañuelas | C33: 70684 | D33: Oeste | E33: 3 | H33: =+N33*0.93 -> 0 | I33: =+H33*0.78 -> 0 | J33: =+I33*0.1599 -> 0 | K33: =+J33*3 -> 0 | L33: =+C33/H33 -> #DIV/0!
A34: GBA | B34: Marcos Paz | C34: 67011 | D34: Oeste | E34: 2 | H34: =+N34*0.93 -> 0 | I34: =+H34*0.78 -> 0 | J34: =+I34*0.1599 -> 0 | K34: =+J34*3 -> 0 | L34: =+C34/H34 -> #DIV/0!
A35: GBA | B35: La Plata | C35: 768470 | D35: Sur | E35: 3 | H35: 322033.89 | I35: =+H35*0.78 -> 251186.43 | J35: =+I35*0.1599 -> 40164.711 | K35: =+J35*3 -> 120494.13 | L35: =+C35/H35 -> 2.3863016
A36: GBA | B36: Zárate | C36: 132221 | D36: Norte | E36: 1 | H36: 47243.07 | I36: =+H36*0.78 -> 36849.595 | J36: =+I36*0.1599 -> 5892.2502 | K36: =+J36*3 -> 17676.751 | L36: =+C36/H36 -> 2.7987385
A37: GBA | B37: Luján | C37: 111008 | D37: Oeste | E37: 2 | H37: 47030.1 | I37: =+H37*0.78 -> 36683.478 | J37: =+I37*0.1599 -> 5865.6881 | K37: =+J37*3 -> 17597.064 | L37: =+C37/H37 -> 2.3603607
A38: GBA | B38: Campana | C38: 110566 | D38: Norte | E38: 1 | H38: 42826.5 | I38: =+H38*0.78 -> 33404.67 | J38: =+I38*0.1599 -> 5341.4067 | K38: =+J38*3 -> 16024.22 | L38: =+C38/H38 -> 2.5817193
A39: GBA | B39: Berisso | C39: 100930 | D39: Sur | E39: 3 | H39: 38516.88 | I39: =+H39*0.78 -> 30043.166 | J39: =+I39*0.1599 -> 4803.9023 | K39: =+J39*3 -> 14411.707 | L39: =+C39/H39 -> 2.6204095
A40: GBA | B40: Ensenada | C40: 63997 | D40: Sur | E40: 3
A41: GBA | B41: Exaltación de la Cruz | C41: 40159 | D41: Norte | E41: 1
...

Sheet P CABA
A1: CABA | B1: (Base 2021 - DNRPA)
A3: Población | B3: Barrio | C3: Zona | D3: Zonificación | E3: Parque Automotor | F3: Autos | G3: Promedio vehículos que reparan | H3: Promedio de Reparación (paños) | I3: Habitante x Vehículo
A4: =+'[1]Parque Automotor 2022'!H22 -> 3121707 | E4: =+'[1]Parque Automotor 2022'!F22 -> 1398169 | F4: =+'[1]Parque Automotor 2022'!B22*0.93 -> 1029258.9 | G4: =+F4*0.1599 -> 164578.5 | H4: =+G4*[1]Mercado!B29 -> 543109.04 | I4: =+A4/F4 -> 3.0329658

Sheet P Pcias
A1: 9 ciudades aportan el 80% de la población y el mercado de la zona Sur exceptuando Caba y Bs As
A3: Recorridos | D3: Tecnico | E3: Distribuidor
A4: Aeropuerto Neuquen | B4: General Roca - Neuquen - Plottier - Cutral Co - Zapala - 250 km | D4: No definido | E4: No definido
A5: Aeropuerto Comodoro | B5: Comodoro - Trelew - Rawson - Madryn - 450 km | D5: No definido | E5: No definido
A6: Aeropuerto Bariloche | B6: Bariloche - San Martín - 260 km | D6: No definido | E6: No definido
A7: Viedma | B7: Visita con circuito Bahía Blanca | D7: No definido | E7: No definido

Sheet Rutas BA

Sheet Tabla Resumen
J1: 1 | K1: Norte | L1: Lucas Gonzalez
J2: 2 | K2: Oeste | L2: Lucas Castiglioni
A3: Suma de Población | D3: Zonificación | J3: 3 | K3: Sur | L3: Hernán Vanucci
A4: Región | B4: Localidad | C4: Distribuidor | D4: 3 | E4: Total general | J4: 4 | K4: Oscilante | L4: Sergio Boscardini
A5: BA GBA | B5: Almirante Brown | C5: Sub Faranda | D5: 584827 | E5: 584827
B6: Avellaneda | C6: Faranda | D6: 367554 | E6: 367554
B7: Berazategui | C7: (en blanco) | D7: 358712 | E7: 358712
B8: Berisso | C8: Faranda | D8: 100930 | E8: 100930
B9: Cañuelas | C9: (en blanco) | D9: 70684 | E9: 70684
B10: Ensenada | C10: Faranda | D10: 63997 | E10: 63997
B11: Esteban Echeverría | C11: (en blanco) | D11: 338480 | E11: 338480
B12: Ezeiza | C12: (en blanco) | D12: 201511 | E12: 201511
B13: Florencio Varela | C13: (en blanco) | D13: 496433 | E13: 496433
B14: La Plata | C14: Faranda | D14: 768470 | E14: 768470
B15: Lanús | C15: D. Colesur | D15: 1 | E15: 1
C16: Lachman | D16: 461267 | E16: 461267
B17: Lomas de Zamora | C17: (en blanco) | D17: 690323 | E17: 690323
B18: Presidente Perón | C18: Meitin | D18: 102106 | E18: 102106
B19: Quilmes | C19: Traversa | D19: 633391 | E19: 633391
B20: San Vicente | C20: (en blanco) | D20: 98215 | E20: 98215
A21: Total BA GBA | D21: 5336901 | E21: 5336901
A22: BA Interior | B22: Adolfo Gonzales Chaves | C22: (en blanco) | D22: 12914 | E22: 12914
B23: Balcarce | C23: Santillan / Lopez | D23: 48982 | E23: 48982
B24: Benito Juárez | C24: (en blanco) | D24: 22292 | E24: 22292
B25: Brandsen | C25: (en blanco) | D25: 32448 | E25: 32448
B26: Castelli | C26: (en blanco) | D26: 9594 | E26: 9594
B27: Chascomús | C27: (en blanco) | D27: 42452 | E27: 42452
B28: Coronel Dorrego | C28: (en blanco) | D28: 15968 | E28: 15968
B29: Coronel Pringles | C29: (en blanco) | D29: 24420 | E29: 24420
B30: Dolores | C30: (en blanco) | D30: 32032 | E30: 32032
B31: General Alvarado | C31: (en blanco) | D31: 45526 | E31: 45526
B32: General Belgrano | C32: (en blanco) | D32: 20791 | E32: 20791
B33: General Guido | C33: (en blanco) | D33: 3174 | E33: 3174
B34: General Juan Madariaga | C34: Romera | D34: 22624 | E34: 22624
... B37: General Pueyrredón | C37: Faranda | D37: 333541 | E37: 333541
C38: Iacono | D38: 333541 | E38: 333541
B39: La Costa | C39: Malelu | D39: 100689 | E39: 100689
B40: Laprida | C40: (en blanco) | D40: 11646 | E40: 11646
B41: Las Flores | C41: (en blanco) | D41: 27239 | E41: 27239
B42: Lezama | C42: (en blanco) | D42: 6221 | E42: 6221
...

Sheet Localidades BA

Sheet GBA

Sheet Tecnicos
A1: Distribucion de zona por Distribuidores
A3: Tecnicos | C3: Rutas | D3: Zonas | E3: Distribuidores PPG actuales
A4: Tecnico 1 | B4: Lucas Gonzalez | D4: Caba Norte | E4: Del Fondo | F4: 4K
A5: Tecnico 1 | D5: Norte | E5: Pintecanal | F5: Caporaso | G5: Quiroga Ana
A6: Tecnico 1 | C6: R9 | D6: Norte Interior | E6: Baradero | F6: Baradero y otros | G6: Jorge Poll
E7: Mena | F7: San pedro | G7: Toyota-Zarate
A9: Tecnico 2 | B9: Lucas Castiglioni | D9: Noroeste | E9: Mymay SRL
A10: Tecnico 2 | C10: R8 | D10: Noroeste Interior | E10: Arrecifes | F10: Salto | G10: Areco
A12: Tecnico 2 | D12: Oeste | E12: Lupatini | F12: Sanzio | G12: Ancona
A13: Tecnico 2 | C13: R7-5 | D13: Oeste Interior | E13: CHM | F13: Impulso
A15: Tecnico 3 | B15: Hernán Vanucci | D15: Caba Sur | E15: Piccin | F15: Marcos | G15: Angrigiani | H15: Disben | I15: Fernandez
A16: Tecnico 3 | D16: Sudoeste | E16: Gianatiempo
A17: Tecnico 3 | C17: R3-205-210 | D17: Sudoeste Interior | E17: Tandil | F17: Tesei | G17: Cabañas | H17: Tres Arroyos | I17: Loberia
A19: Tecnico 4 | B19: Sergio Boscardini | D19: Sur | E19: Faranda | F19: Migliore | G19: El Sol | H19: Traversa | I19: Dstrisur | J19: Colesur
A20: Tecnico 4 | C20: R2 | D20: Sur Interior | E20: Faranda | F20: Iacono | G20: Balcarce
D21: Bahía
A22: Tecnicos Varios | D22: La Pampa | E22: n/a
A23: Tecnicos Varios | D23: Patagonia | E23: Pinturerias Colorama | F23: Club De Color Pintureria | G23: Acuarela- P. Madryn | H23: Sato Pinturas Automotor
